<?xml version="1.0" ?>
<robot name="fishbot"
  xmlns:xacro="http://ros.org/wiki/xacro">
  <!-- <xacro:include filename="$(find fishbot_description)/urdf/common_properties.urdf"/> -->

  <!-- Init colour -->
  <material name="black">
      <color rgba="0.0 0.0 0.0 1.0"/>
  </material>

  <material name="dark">
    <color rgba="0.3 0.3 0.3 1.0"/>
  </material>

  <material name="light_black">
    <color rgba="0.4 0.4 0.4 1.0"/>
  </material>

  <material name="blue">
    <color rgba="0.0 0.0 0.8 1.0"/>
  </material>

  <material name="green">
    <color rgba="0.0 0.8 0.0 1.0"/>
  </material>

  <material name="grey">
    <color rgba="0.5 0.5 0.5 1.0"/>
  </material>

  <material name="orange">
    <color rgba="1.0 0.4235 0.0392 1.0"/>
  </material>

  <material name="brown">
    <color rgba="0.8706 0.8118 0.7647 1.0"/>
  </material>

  <material name="red">
    <color rgba="0.8 0.0 0.0 1.0"/>
  </material>

  <material name="white">
    <color rgba="1.0 1.0 1.0 1.0"/>
  </material>

  <link name="base_footprint"/> 

  <joint name="base_joint" type="fixed">
    <parent link="base_footprint"/>
    <child link="base_link"/>
    <origin xyz="0.0 0.0 0.010" rpy="0 0 0"/>
  </joint>


  <link name="base_link">
    <visual>
      
      <geometry>
        <mesh filename="package://fishbot_description/meshes/bases/burger_base.stl" scale="0.001 0.001 0.001"/>
      </geometry>
      <material name="light_black"/>
    </visual>

    <collision>
      <origin xyz="-0.032 0 0.070" rpy="0 0 0"/>
      <geometry>
        <box size="0.140 0.140 0.143"/>
      </geometry>
    </collision>

    <inertial>
      <origin xyz="0 0 0" rpy="0 0 0"/>
      <mass value="8.2573504e-01"/>
      <inertia ixx="2.2124416e-03" ixy="-1.2294101e-05" ixz="3.4938785e-05" iyy="2.1193702e-03" iyz="-5.0120904e-06" izz="2.0064271e-03" />
    </inertial>
  </link>

  <joint name="wheel_left_joint" type="continuous">
    <parent link="base_link"/>
    <child link="wheel_left_link"/>
    <origin xyz="0.0 0.08 0.023" rpy="-1.57 0 0"/>
    <axis xyz="0 0 1"/>
  </joint>

  <link name="wheel_left_link">
    <visual>
      <origin xyz="0 0 0" rpy="1.57 0 0"/>
      <geometry>
        <mesh filename="package://fishbot_description/meshes/wheels/left_tire.stl" scale="0.001 0.001 0.001"/>
      </geometry>
      <material name="dark"/>
    </visual>

    <collision>
      <origin xyz="0 0 0" rpy="0 0 0"/>
      <geometry>
        <cylinder length="0.018" radius="0.033"/>
      </geometry>
    </collision>

    <inertial>
      <origin xyz="0 0 0" />
      <mass value="2.8498940e-02" />
      <inertia ixx="1.1175580e-05" ixy="-4.2369783e-11" ixz="-5.9381719e-09" iyy="1.1192413e-05" iyz="-1.4400107e-11" izz="2.0712558e-05" />
    </inertial>
  </link>

  <joint name="wheel_right_joint" type="continuous">
    <parent link="base_link"/>
    <child link="wheel_right_link"/>
    <origin xyz="0.0 -0.080 0.023" rpy="-1.57 0 0"/>
    <axis xyz="0 0 1"/>
  </joint>

  <link name="wheel_right_link">
    <visual>
      <origin xyz="0 0 0" rpy="1.57 0 0"/>
      <geometry>
        <mesh filename="package://fishbot_description/meshes/wheels/right_tire.stl" scale="0.001 0.001 0.001"/>
      </geometry>
      <material name="dark"/>
    </visual>

    <collision>
      <origin xyz="0 0 0" rpy="0 0 0"/>
      <geometry>
        <cylinder length="0.018" radius="0.033"/>
      </geometry>
    </collision>

    <inertial>
      <origin xyz="0 0 0" />
      <mass value="2.8498940e-02" />
      <inertia ixx="1.1175580e-05" ixy="-4.2369783e-11" ixz="-5.9381719e-09" iyy="1.1192413e-05" iyz="-1.4400107e-11" izz="2.0712558e-05" />
    </inertial>
  </link>

  <joint name="caster_back_joint" type="fixed">
    <parent link="base_link"/>
    <child link="caster_back_link"/>
    <origin xyz="-0.081 0 -0.004" rpy="-1.57 0 0"/>
  </joint>

  <link name="caster_back_link">
    <collision>
      <origin xyz="0 0.001 0" rpy="0 0 0"/>
      <geometry>
        <box size="0.030 0.009 0.020"/>
      </geometry>
    </collision>

    <inertial>
      <origin xyz="0 0 0" />
      <mass value="0.005" />
      <inertia ixx="0.001" ixy="0.0" ixz="0.0" iyy="0.001" iyz="0.0" izz="0.001" />
    </inertial>
  </link>

  <joint name="imu_joint" type="fixed">
    <parent link="base_link"/>
    <child link="imu_link"/>
    <origin xyz="-0.032 0 0.068" rpy="0 0 0"/>
  </joint>

  <link name="imu_link"/>

  <joint name="scan_joint" type="fixed">
    <parent link="base_link"/>
    <child link="base_scan"/>
    <origin xyz="-0.032 0 0.172" rpy="0 0 0"/>
  </joint>

  <link name="base_scan">
    <visual>
      <origin xyz="0 0 0.0" rpy="0 0 0"/>
      <geometry>
        <mesh filename="package://fishbot_description/meshes/sensors/lds.stl" scale="0.001 0.001 0.001"/>
      </geometry>
      <material name="dark"/>
    </visual>

    <collision>
      <origin xyz="0.015 0 -0.0065" rpy="0 0 0"/>
      <geometry>
        <cylinder length="0.0315" radius="0.055"/>
      </geometry>
    </collision>

    <inertial>
      <mass value="0.114" />
      <origin xyz="0 0 0" />
      <inertia ixx="0.001" ixy="0.0" ixz="0.0" iyy="0.001" iyz="0.0" izz="0.001" />
    </inertial>
  </link>



<!-- //   arm   // -->
    <joint name="base_arm" type="fixed">
      <parent link="base_link"/>
      <child link="bottom"/>
      <origin xyz="0.03 0 0.16" rpy="0 0 0"/>
    </joint>

    <link name="bottom">
		<visual>
			<origin rpy="0 0 0" xyz="0 0 0"/>
			<geometry>
				<cylinder length="0.04" radius="0.02"/>
			</geometry>
			<material name="White"/>
		</visual>
	</link>
<!-- ///   LINK1  // -->
    <joint name="joint1" type="revolute">
		<parent link="bottom"/>
		<child link="link1"/>
		<origin rpy="0 1.5707 0" xyz="0 0 0.02"/>
		<axis xyz="-1 0 0"/>
		<limit effort="300" lower="-3.14159" upper="3.14159" velocity="1"/>
	</joint>

	<link name="link1">
		<visual>
			<origin rpy="0 1.5707 0" xyz="-0.05 0 0"/>
			<geometry>
				<cylinder length="0.1" radius="0.015"/>
			</geometry>
			<material name="Blue"/>
		</visual>
	</link>

<!-- ///   LINK2  // -->
	<link name="link2">
		<visual>
			<origin rpy="0 0 0" xyz="0 0 0.07"/>
			<geometry>
				<cylinder length="0.14" radius="0.015"/>
			</geometry>
			<material name="White"/>
		</visual>
	</link>

	<joint name="joint2" type="revolute">
		<parent link="link1"/>
		<child link="link2"/>
		<origin rpy="-1.5707 0 1.5707" xyz="-0.1 0 0.0"/>
		<axis xyz="1 0 0"/>
		<limit effort="300" lower="-3.14159" upper="3.14159" velocity="1"/>
	</joint>

<!-- /   LINK3  / -->
	<link name="link3">
		<visual>
			<origin rpy="0 0 0" xyz="0 0 -0.075"/>
			<geometry>
				<cylinder length="0.15" radius="0.015"/>
			</geometry>
			<material name="Blue"/>
		</visual>
	</link>

	<joint name="joint3" type="revolute">
		<parent link="link2"/>
		<child link="link3"/>
		<origin rpy="0 3.14159 0" xyz="0 0 0.14"/>
		<axis xyz="-1 0 0"/>
		<limit effort="300" lower="-3.14159" upper="3.14159" velocity="1"/>
	</joint>

<!-- ///   LINK4   -->
	<link name="link4">
		<visual>
			<origin rpy="0 1.5707 0" xyz="0.03 0 0"/>
			<geometry>
				<cylinder length="0.06" radius="0.01"/>
			</geometry>
			<material name="Black"/>
		</visual>
	</link>

	<joint name="joint4" type="revolute">
		<parent link="link3"/>
		<child link="link4"/>
		<origin rpy="0 1.5707 3.14159" xyz="0.0 0.0 -0.15"/>
		<axis xyz="1 0 0"/>
		<limit effort="300" lower="-3.14159" upper="3.14159" velocity="1"/>
	</joint>

<!-- //   LINK5  / -->
	<link name="link5">
		<visual>
			<origin rpy="0 0 0" xyz="0 0 0.03"/>
			<geometry>
				<cylinder length="0.06" radius="0.02"/>
			</geometry>
			<material name="White"/>
		</visual>
	</link>

	<joint name="joint5" type="revolute">
		<parent link="link4"/>
		<child link="link5"/>
		<origin rpy="0 1.5707 0" xyz="0.06 0.0 0.0"/>
		<axis xyz="1 0 0"/>
		<limit effort="300" lower="-3.14159" upper="3.14159" velocity="1"/>
	</joint>

<!--    LINK6  / -->
	<link name="link6">
		<visual>
			<origin rpy="0 1.5707 0" xyz="0.01 0 0 "/>
			<geometry>
				<cylinder length="0.02" radius="0.015"/>
			</geometry>
			<material name="Blue"/>
		</visual>
	</link>

	<joint name="joint6" type="revolute">
		<parent link="link5"/>
		<child link="link6"/>
		<origin rpy="4.712385 -1.5707 0" xyz="0 0 0.06"/>
		<axis xyz="1 0 0"/>
		<limit effort="300" lower="-6.28318" upper="6.28318" velocity="1"/>
	</joint>

<!-- //   GRIPPER   // -->
	<link name="gripper_finger_link1">
		<visual>
			<origin rpy="0 1.5707 0" xyz="0.03 0 0"/>
			<geometry>
				<box size="0.01 0.006 0.04"/>
			</geometry>
			<material name="White"/>
		</visual>
	</link>

	<link name="gripper_finger_link2">
		<visual>
			<origin rpy="0 1.5707 0" xyz="0.03 0 0"/>
			<geometry>
				<box size="0.01 0.006 0.04"/>
			</geometry>
			<material name="White"/>
		</visual>
	</link>

	<joint name="finger_joint1" type="prismatic">
		<parent link="link6"/>
		<child link="gripper_finger_link1"/>
		<origin rpy="0 0 0" xyz="0.04 -0.015 -0.025"/>
		<axis xyz="0 1 0"/>
		<limit effort="100" lower="0" upper="0.015" velocity="0.02"/>
	</joint>

	<joint name="finger_joint2" type="fixed">
		<parent link="link6"/>
		<child link="gripper_finger_link2"/>
		<origin rpy="0 0 0" xyz="0.04 0.015 -0.025"/>
	</joint>

</robot>
